Workbook

Sheet Dimensionamento
A1: Pedro Kzan - Eng. Elétrica | EESC USP
A3: Dimensionamento de Sistema Fotovoltaico ON-GRID para usuário micro ou minigerador com Payback - Dimens. Inicial
C5: À direita das células preenchíveis, seguem explicações. | G5: Legenda: | H5: Dados alteráveis:
A6: Dados Indicados (inputs) | H6: Dados fixos:
A7: Classe do Usuário | E7: B | G7: Disponível na conta de energia, assim como o modelo tarifário. | L7: Grupo B: tensão menor que 2,3kV
A8: Modelo tarifário | E8: Branca | L8: Grupo A: tensão maior que 2,3kV
A9: Cidade | E9: São Carlos
A10: Tmin | E10: 5 | F10: ºC. | H10: Energia de Custo de Disponibilidade (Grupo B): | K10: Sistema monofásico: 30kWh
A11: Latitude | E11: 23 | F11: º/Sul. | K11: Sistema bifásico (3 fios): 50kWh
A12: Longitude | E12: 48 | F12: º/Oeste. | K12: Sistema trifásico: 100kWh
A13: Irradiação Solar (GHI) | E13: 5.21 | F13: *Sundata.
A14: (Grupo B) custo consumo TUSD (R$/kWh) | E14: 0.44925 | F14: Da conta de energia, disponível lá ou publicamente pela concessionária. *Se for tarifa branca, escolher o horário fora de ponta para facilitar cálculo. Espere um retorno 5-9% maior na realidade
A15: (Grupo B) custo consumo TE (R$/kWh) | E15: 0.2902 | F15: Se não há TUSD e TE separados na conta de energia, considere TE=TUSD.
A16: (Grupo A) c. cons. Fponta TUSD cheio (R$/kWh) | F16: TE: custo da energia; TUSD: custo do transporte dela.
A17: (Grupo A) c. cons. Fponta TE cheio (R$/kWh) | F17: https://portalrelatorios.aneel.gov.br/luznatarifa/basestarifas | J17: *Por fins de aproximação, desconsidero a ponta para o cálculo de Payback pois em Pernambuco ponta começa às 17:30, mas no horário a geração é tão pouca que desconsidero para facilitar cálculos.
A18: (Grupo A) c. cons. Fponta TUSD SCEE (R$/kWh) | F18: *Energia injetada
A19: (Grupo A) c. cons. Fponta TE SCEE (R$/kWh)
A20: (Grupo A) c. demanda geração TUSDG (R$/kWh)
A21: Fio B | F21: https://institutosolar.com/como-calcular-o-valor-do-fio-b-para-energia-solar/#:~:text=Para%20se%20obter%20o%20valor,Tarifas%20%3E%3E%20Relat%C3%B3rios%20e%20Indicadores.
A22: Porcentagem fio B | E22: 0.9 | F22: 90% = base 2029, irá mudar com nova resolução ANEEL
A23: Energia Mensal (EM) | E23: 641 | F23: kWh/mês.
A24: Eficiência do sistema todo (ηsis) | E24: 0.8 | F24: Escolher entre [0,7-0,9] -> perdas surgem de temperatura, inversor, sujeira/poeira, cabeamento, mismatch, sombreamento, degradação.
A25: Potência do Painel (PMOD) | E25: 550 | F25: W -> escolha do projetista.
A26: Sobrecarga do Inversor (PCC/PCA) | E26: 1.1 | F26: Escolher entre [1-1,25] -> conferir no manual do inversor.
A27: Tensão em Vazio do Módulo | E27: 49.6 | F27: V vide datasheet do módulo.
A28: Coeficiente de temperatura do módulo (α) | E28: -0.0029 | F28: Vide datasheet do módulo.
A29: Nº de MPPTs do Inversor | E29: 2 | F29: Conexões no inversor.
A31: Dimensionamento Preliminar (outputs)
A32: Consumo de energia do cliente | E32: =E23 -> 641 | F32: Energia média mensal (kWh/mês) obtida da conta de energia; média dos últimos 12 meses.
A33: (Grupo B) Custo de energia consumida | E33: =(E14+E15) -> 0.73945 | F33: R$/kWh.
A34: (Grupo B) custo de energia injetada | E34: =$E$14+$E$15*(1-Payback!$E$13) -> 0.65239 | F34: R$/kWh.
A35: (Grupo A) custo E consumo Fponta | E35: =E16+E17 -> 0 | F35: R$/kWh.
A36: (Grupo A) custo energia injetada | E36: =$E$19+$E$18*(1-Payback!$E$13) -> 0 | F36: R$/kWh. Desconsiderar se é grupo B
A37: (Grupo A) Demanda de geração contratada ótima | E37: =E42/1000 -> 5 | F37: kW, aproximado
A38: Potência Fotovoltaica teórica | E38: =E32*1000/(30*E24*E13) -> 5126.3596 | F38: W; PFV=1000*EFV/(30*GHI*ηsis).
A39: Número de módulos | E39: =ROUNDUP(E38/E25,0) -> 10 | F39: (Arredondado pra cima).
A40: Nº de módulos/Nº de MPPT | E40: =ROUND(E39/E29,0) -> 5
A41: Potência Fotovoltaica real | E41: =E39*E25 -> 5500 | F41: W (com nº inteiro de módulos).
A42: Potência do Inversor em CA | E42: =E41/E26 -> 5000 | F42: W; aproximado.
A43: Energia Fotovoltaica real | E43: =30*E13*E24*E42/1000 -> 625.2 | F43: kWh; Geração estimada, a potência é a nominal do inversor
...

Sheet Payback
B1: Viabilidade Econômica
G2: Dados alteráveis: | O2: Células Auxiliares + Porcentagem FioB (desconta na injetada)
B3: Fatores de Influência Adotados | E3: Valor | G3: Dados fixos: | O3: TE_ef cheio | P3: =IF(Dimensionamento!$E$7="A",Dimensionamento!$E$17,Dimensionamento!$E$15) -> 0.2902 | Q3: TE_ef SCEE (GA) | R3: =Dimensionamento!$E$19
B4: Previsão de aumento do custo Energia | E4: 0.075 | F4: /ano | H4: Baseado no aumento médio do custo da energia nos últimos anos. | O4: TUSD_ef cheio | P4: =IF(Dimensionamento!$E$7="A",Dimensionamento!$E$16,Dimensionamento!$E$14) -> 0.44925 | Q4: TUSD SCEE (GA) | R4: =Dimensionamento!$E$18
B5: Taxa de Autoconsumo | E5: 0.3 | F5: *Qnt. geração usada para suprir o próprio consumo, não injetada - residência, escolher entre 20-40% se não houver armazenamento (BESS); com BESS, depende da estratégia adotada no sistema. | O5: FioB_ef | P5: =Dimensionamento!E21 | Q5: *Base para uso futuro
B6: Taxa de Desconto | E6: 0.1 | F6: /ano | H6: Taxa usada para cálculo do Fluxo Descontado e VPL. | O6: Porcentagem Fio B | P6: =Dimensionamento!$E$22 -> 0.9 | Q6: 90% = base (2029) até nova resolução ANEEL. *Base para uso futuro
B7: Vida útil do inversor | E7: 15 | F7: anos | H7: Estimativa.
B8: Custo de manutenção em relação à economia anual | E8: 0.01 | F8: Em torno de 1%-5% do custo de Energia Gerada para limpeza do módulos.
B9: Custos total do inversor em relação à economia anual | E9: 0.7 | F9: Em torno de 30-70%. Apenas para efeitos de troca do inversor após a vida útil.
B10: Perda de eficiencia do painel | E10: 0.02 | F10: 1º ano.
B11: Perda de eficiencia do painel (outros anos) | E11: 0.008 | F11: 2º ano em diante.
B12: Cenário: Pessimista (1); Base (2); Otimista (3) | E12: 2 | F12: *Será decidido pela ANEEL nova valorização da energia injetável. Escolhi cenário 1: só vale TE; cenário 2: TE+TUSD-FioB*%; cenário 3: preço cheio, TE+TUSD (teto, benefícios).
B13: FioB% do TUSD (estimativa geral) | E13: 0.3 | F13: Pois o FioB é uma tarifa baseada na TUSD. Conforme TUSD aumenta de valor, FioB também aumenta e pode mudar de forma independente por outras dinâmicas
J14: Payback simples | L14: Payback descontado (supondo desvalorização)
C15: Ano | D15: Energia Anual Gerada (kWh) | E15: Custo do kWh de Energia Consumida (R$) | F15: Custo do kWh de Energia Injetada (R$) | G15: Economia (R$) | H15: Manutenção (R$) | I15: Fluxo de Caixa Anual (R$) | J15: Fluxo Acumulado (R$) | K15: Fluxo Descontado (R$) | L15: Fluxo Descontado Acumulado (R$)
C16: 0 | I16: =-Dimensionamento!G75 -> -21840 | J16: =I16 -> -21840 | K16: =I16 -> -21840 | L16: =I16 -> -21840
C17: 1 | D17: =Dimensionamento!E43*12 -> 7502.4 | E17: =P3+P4 -> 0.73945 | F17: =IF(Dimensionamento!$E$7="A", IF($E$12=1, $R$3, IF($E$12=2, $R$3+$R$4*(1-$E$13), $R$3+$R$4)), IF($E$12=1, $P$3, IF($E$12=2, $P$3+$P$4*(1-$E$13), $P$3+$P$4))) -> 0.604675 | G17: =(E17*$E$5+(1-$E$5)*F17)*D17 -> 4839.8545 | H17: =IF(OR(C17=$E$7,C17=2*$E$7),G17*($E$8+$E$9),G17*$E$8) -> 48.398545 | I17: =G17-H17- IF(Dimensionamento!$E$7="A", Dimensionamento!$E$37*Dimensionamento!$E$20*12, 0) -> 4791.456 | J17: =J16+I17 -> -17048.544 | K17: =I17/(1+$E$6)^C17 -> 4355.8691 | L17: =L16+K17 -> -17484.131
C18: 2 | D18: =Dimensionamento!$E$43*12*(1-$E$10) -> 7352.352 | E18: =E17*(1+$E$4) -> 0.79490875 | F18: =F17*(1+$E$4) -> 0.65002563 | G18: =(E18*$E$5+(1-$E$5)*F18)*D18 -> 5098.7867 | H18: =IF(OR(C18=$E$7,C18=2*$E$7),G18*($E$8+$E$9),G18*$E$8) -> 50.987867 | I18: =G18-H18- IF(Dimensionamento!$E$7="A", Dimensionamento!$E$37*Dimensionamento!$E$20*12, 0) -> 5047.7989 | J18: =J17+I18 -> -12000.745 | K18: =I18/(1+$E$6)^C18 -> 4171.7346 | L18: =L17+K18 -> -13312.396
C19: 3 | D19: =Dimensionamento!$E$43*12*(1-$E$10-(C19-2)*$E$11) -> 7292.3328 | E19: =E18*(1+$E$4) -> 0.85452691 | F19: =F18*(1+$E$4) -> 0.69877755 | G19: =(E19*$E$5+(1-$E$5)*F19)*D19 -> 5436.4513 | H19: =IF(OR(C19=$E$7,C19=2*$E$7),G19*($E$8+$E$9),G19*$E$8) -> 54.364513 | I19: =G19-H19- IF(Dimensionamento!$E$7="A", Dimensionamento!$E$37*Dimensionamento!$E$20*12, 0) -> 5382.0868 | J19: =J18+I19 -> -6618.6584 | K19: =I19/(1+$E$6)^C19 -> 4043.6414 | L19: =L18+K19 -> -9268.7549
C20: 4 | D20: =Dimensionamento!$E$43*12*(1-$E$10-(C20-2)*$E$11) -> 7232.3136 | E20: =E19*(1+$E$4) -> 0.91861642 | F20: =F19*(1+$E$4) -> 0.75118586 | G20: =(E20*$E$5+(1-$E$5)*F20)*D20 -> 5796.0848 | H20: =IF(OR(C20=$E$7,C20=2*$E$7),G20*($E$8+$E$9),G20*$E$8) -> 57.960848 | I20: =G20-H20- IF(Dimensionamento!$E$7="A", Dimensionamento!$E$37*Dimensionamento!$E$20*12, 0) -> 5738.124 | J20: =J19+I20 -> -880.53444 | K20: =I20/(1+$E$6)^C20 -> 3919.2159 | L20: =L19+K20 -> -5349.539
C21: 5 | D21: =Dimensionamento!$E$43*12*(1-$E$10-(C21-2)*$E$11) -> 7172.2944 | E21: =E20*(1+$E$4) -> 0.98751266 | F21: =F20*(1+$E$4) -> 0.8075248 | G21: =(E21*$E$5+(1-$E$5)*F21)*D21 -> 6179.0834 | H21: =IF(OR(C21=$E$7,C21=2*$E$7),G21*($E$8+$E$9),G21*$E$8) -> 61.790834 | I21: =G21-H21- IF(Dimensionamento!$E$7="A", Dimensionamento!$E$37*Dimensionamento!$E$20*12, 0) -> 6117.2925 | J21: =J20+I21 -> 5236.7581 | K21: =I21/(1+$E$6)^C21 -> 3798.3574 | L21: =L20+K21 -> -1551.1816
C22: 6 | D22: =Dimensionamento!$E$43*12*(1-$E$10-(C22-2)*$E$11) -> 7112.2752 | E22: =E21*(1+$E$4) -> 1.0615761 | F22: =F21*(1+$E$4) -> 0.86808916 | G22: =(E22*$E$5+(1-$E$5)*F22)*D22 -> 6586.9287 | H22: =IF(OR(C22=$E$7,C22=2*$E$7),G22*($E$8+$E$9),G22*$E$8) -> 65.869287 | I22: =G22-H22- IF(Dimensionamento!$E$7="A", Dimensionamento!$E$37*Dimensionamento!$E$20*12, 0) -> 6521.0595 | J22: =J21+I22 -> 11757.818 | K22: =I22/(1+$E$6)^C22 -> 3680.9681 | L22: =L21+K22 -> 2129.7864
C23: 7 | D23: =Dimensionamento!$E$43*12*(1-$E$10-(C23-2)*$E$11) -> 7052.256 | E23: =E22*(1+$E$4) -> 1.1411943 | F23: =F22*(1+$E$4) -> 0.93319585 | G23: =(E23*$E$5+(1-$E$5)*F23)*D23 -> 7021.1936 | H23: =IF(OR(C23=$E$7,C23=2*$E$7),G23*($E$8+$E$9),G23*$E$8) -> 70.211936 | I23: =G23-H23- IF(Dimensionamento!$E$7="A", Dimensionamento!$E$37*Dimensionamento!$E$20*12, 0) -> 6950.9816 | J23: =J22+I23 -> 18708.799 | K23: =I23/(1+$E$6)^C23 -> 3566.9526 | L23: =L22+K23 -> 5696.7391
C24: 8 | D24: =Dimensionamento!$E$43*12*(1-$E$10-(C24-2)*$E$11) -> 6992.2368 | E24: =E23*(1+$E$4) -> 1.2267839 | F24: =F23*(1+$E$4) -> 1.0031855 | G24: =(E24*$E$5+(1-$E$5)*F24)*D24 -> 7483.5466 | H24: =IF(OR(C24=$E$7,C24=2*$E$7),G24*($E$8+$E$9),G24*$E$8) -> 74.835466 | I24: =G24-H24- IF(Dimensionamento!$E$7="A", Dimensionamento!$E$37*Dimensionamento!$E$20*12, 0) -> 7408.7112 | J24: =J23+I24 -> 26117.51 | K24: =I24/(1+$E$6)^C24 -> 3456.2184 | L24: =L23+K24 -> 9152.9575
C25: 9 | D25: =Dimensionamento!$E$43*12*(1-$E$10-(C25-2)*$E$11) -> 6932.2176 | E25: =E24*(1+$E$4) -> 1.3187927 | F25: =F24*(1+$E$4) -> 1.0784245 | G25: =(E25*$E$5+(1-$E$5)*F25)*D25 -> 7975.7584 | H25: =IF(OR(C25=$E$7,C25=2*$E$7),G25*($E$8+$E$9),G25*$E$8) -> 79.757584 | I25: =G25-H25- IF(Dimensionamento!$E$7="A", Dimensionamento!$E$37*Dimensionamento!$E$20*12, 0) -> 7896.0008 | J25: =J24+I25 -> 34013.511 | K25: =I25/(1+$E$6)^C25 -> 3348.6752 | L25: =L24+K25 -> 12501.633
C26: 10 | D26: =Dimensionamento!$E$43*12*(1-$E$10-(C26-2)*$E$11) -> 6872.1984 | E26: =E25*(1+$E$4) -> 1.4177021 | F26: =F25*(1+$E$4) -> 1.1593063 | G26: =(E26*$E$5+(1-$E$5)*F26)*D26 -> 8499.7071 | H26: =IF(OR(C26=$E$7,C26=2*$E$7),G26*($E$8+$E$9),G26*$E$8) -> 84.997071 | I26: =G26-H26- IF(Dimensionamento!$E$7="A", Dimensionamento!$E$37*Dimensionamento!$E$20*12, 0) -> 8414.71 | J26: =J25+I26 -> 42428.221 | K26: =I26/(1+$E$6)^C26 -> 3244.235 | L26: =L25+K26 -> 15745.868
C27: 11 | D27: =Dimensionamento!$E$43*12*(1-$E$10-(C27-2)*$E$11) -> 6812.1792 | E27: =E26*(1+$E$4) -> 1.5240298 | F27: =F26*(1+$E$4) -> 1.2462543 | G27: =(E27*$E$5+(1-$E$5)*F27)*D27 -> 9057.3844 | H27: =IF(OR(C27=$E$7,C27=2*$E$7),G27*($E$8+$E$9),G27*$E$8) -> 90.573844 | I27: =G27-H27- IF(Dimensionamento!$E$7="A", Dimensionamento!$E$37*Dimensionamento!$E$20*12, 0) -> 8966.8105 | J27: =J26+I27 -> 51395.032 | K27: =I27/(1+$E$6)^C27 -> 3142.8124 | L27: =L26+K27 -> 18888.68
C28: 12 | D28: =Dimensionamento!$E$43*12*(1-$E$10-(C28-2)*$E$11) -> 6752.16 | E28: =E27*(1+$E$4) -> 1.638332 | F28: =F27*(1+$E$4) -> 1.3397233 | G28: =(E28*$E$5+(1-$E$5)*F28)*D28 -> 9650.9024 | H28: =IF(OR(C28=$E$7,C28=2*$E$7),G28*($E$8+$E$9),G28*$E$8) -> 96.509024 | I28: =G28-H28- IF(Dimensionamento!$E$7="A", Dimensionamento!$E$37*Dimensionamento!$E$20*12, 0) -> 9554.3934 | J28: =J27+I28 -> 60949.425 | K28: =I28/(1+$E$6)^C28 -> 3044.3242 | L28: =L27+K28 -> 21933.004
C29: 13 | D29: =Dimensionamento!$E$43*12*(1-$E$10-(C29-2)*$E$11) -> 6692.1408 | E29: =E28*(1+$E$4) -> 1.7612069 | F29: =F28*(1+$E$4) -> 1.4402026 | G29: =(E29*$E$5+(1-$E$5)*F29)*D29 -> 10282.5 | H29: =IF(OR(C29=$E$7,C29=2*$E$7),G29*($E$8+$E$9),G29*$E$8) -> 102.825 | I29: =G29-H29- IF(Dimensionamento!$E$7="A", Dimensionamento!$E$37*Dimensionamento!$E$20*12, 0) -> 10179.675 | J29: =J28+I29 -> 71129.1 | K29: =I29/(1+$E$6)^C29 -> 2948.6893 | L29: =L28+K29 -> 24881.694
C30: 14 | D30: =Dimensionamento!$E$43*12*(1-$E$10-(C30-2)*$E$11) -> 6632.1216 | E30: =E29*(1+$E$4) -> 1.8932974 | F30: =F29*(1+$E$4) -> 1.5482178 | G30: =(E30*$E$5+(1-$E$5)*F30)*D30 -> 10954.552 | H30: =IF(OR(C30=$E$7,C30=2*$E$7),G30*($E$8+$E$9),G30*$E$8) -> 109.54552 | I30: =G30-H30- IF(Dimensionamento!$E$7="A", Dimensionamento!$E$37*Dimensionamento!$E$20*12, 0) -> 10845.006 | J30: =J29+I30 -> 81974.106 | K30: =I30/(1+$E$6)^C30 -> 2855.8291 | L30: =L29+K30 -> 27737.523
... C46: 30 | D46: =Dimensionamento!$E$43*12*(1-$E$10-(C46-2)*$E$11) -> 5671.8144 | E46: =E45*(1+$E$4) -> 6.0221875 | F46: =F45*(1+$E$4) -> 4.9245605 | G46: =(E46*$E$5+(1-$E$5)*F46)*D46 -> 29798.854 | H46: =IF(OR(C46=$E$7,C46=2*$E$7),G46*($E$8+$E$9),G46*$E$8) -> 21157.186 | I46: =G46-H46- IF(Dimensionamento!$E$7="A", Dimensionamento!$E$37*Dimensionamento!$E$20*12, 0) -> 8641.6677 | J46: =J45+I46 -> 361251.06 | K46: =I46/(1+$E$6)^C46 -> 495.24147 | L46: =L45+K46 -> 59640.03
C49: VPL | D49: =SUM(K16:K46) -> 59640.03
C50: TIR | D50: =IRR(I16:I46) -> 0.28015341
B52: VPL (Valor Presente Líquido): Soma de todos os fluxos de caixa trazidos a valor presente pela taxa de desconto, incluindo o investimento inicial. Representa o ganho líquido do projeto em valores de hoje. VPL > 0 indica que o projeto se paga e ainda gera retorno acima da taxa de desconto adotada. Sua progressão pode ser vista no fluxo descontado.
B56: TIR (Taxa Interna de Retorno): Taxa de desconto que zera o VPL; representa a rentabilidade equivalente do investimento.
