Workbook

Sheet Dimensionamento
A1: Pedro Kzan - Eng. Elétrica | EESC USP
A3: Dimensionamento de Sistema Fotovoltaico ON-GRID para usuário micro ou minigerador com Payback - Dimens. Inicial
C5: À direita das células preenchíveis, seguem explicações. | G5: Legenda: | H5: Dados alteráveis:
A6: Dados Indicados (inputs) | H6: Dados fixos:
A7: Classe do Usuário | E7: B | F7: Disponível na conta de energia, assim como o modelo tarifário. | L7: Grupo B: tensão menor que 2,3kV
A8: Modelo tarifário | E8: - | L8: Grupo A: tensão maior que 2,3kV
A9: Cidade | E9: São Carlos
A10: Tmin | E10: 5 | F10: ºC. | H10: Energia de Custo de Disponibilidade (Grupo B): | K10: Sistema monofásico: 30kWh
A11: Latitude | E11: 23 | F11: º/Sul. | K11: Sistema bifásico (3 fios): 50kWh
A12: Longitude | E12: 48 | F12: º/Oeste. | K12: Sistema trifásico: 100kWh
A13: Irradiação Solar (GHI) | E13: 5.21 | F13: *Sundata.
A14: (Grupo B) custo consumo TUSD (R$/kWh) | E14: 0.44925 | F14: Da conta de energia, disponível lá ou publicamente pela concessionária. *Se for tarifa branca, escolher o horário fora de ponta para facilitar cálculo. Espere um retorno 5-9% maior na realidade
A15: (Grupo B) custo consumo TE (R$/kWh) | E15: 0.30905 | F15: Se não há TUSD e TE separados na conta de energia, considere TE=TUSD.
A16: (Grupo A) consumo Fponta TUSD | F16: TE: custo da energia; TUSD: custo do transporte dela.
A17: (Grupo A) consumo Fponta TE | F17: Por fins de aproximação, desconsidero a ponta para o cálculo de Payback pois em Pernambuco ponta começa às 17:30, mas no horário a geração é tão pouca que desconsidero para facilitar cálculos.
A18: (Grupo A) custo demanda de geração TUSDG
A19: Fio B | E19: 0.18801 | F19: https://institutosolar.com/como-calcular-o-valor-do-fio-b-para-energia-solar/#:~:text=Para%20se%20obter%20o%20valor,Tarifas%20%3E%3E%20Relat%C3%B3rios%20e%20Indicadores.
A20: Porcentagem fio B | E20: 0.9 | F20: 90% = base 2029, irá mudar com nova resolução ANEEL
A21: Energia Mensal (EM) | E21: 641 | F21: kWh/mês.
A22: Eficiência do sistema todo (ηsis) | E22: 0.8 | F22: Escolher entre [0,7-0,9] -> perdas surgem de temperatura, inversor, sujeira/poeira, cabeamento, mismatch, sombreamento, degradação.
A23: Potência do Painel (PMOD) | E23: 550 | F23: W -> escolha do projetista.
A24: Sobrecarga do Inversor (PCC/PCA) | E24: 1.15 | F24: Escolher entre [1-1,25] -> conferir no manual do inversor.
A25: Tensão em Vazio do Módulo | E25: 49.6 | F25: V vide datasheet do módulo.
A26: Coeficiente de temperatura do módulo (α) | E26: -0.0029 | F26: Vide datasheet do módulo.
A27: Nº de MPPTs do Inversor | E27: 2 | F27: Conexões no inversor.
A29: Dimensionamento Preliminar (outputs)
A30: Consumo de energia do cliente | E30: =E21 -> 641 | F30: Energia média mensal (kWh/mês) obtida da conta de energia; média dos últimos 12 meses.
A31: (Grupo B) Custo de energia consumida | E31: =(E14+E15) -> 0.7583 | F31: R$/kWh.
A32: (Grupo B) custo de energia injetada | E32: =$E$14+$E$15-$E$19*Payback!$P$6 -> 0.589091 | F32: R$/kWh.
A33: (Grupo A) custo E consumo Fponta | E33: =E16+E17 -> 0 | F33: R$/kWh.
A34: (Grupo A) custo energia injetada | E34: =$E$16+$E$17-$E$19*$E$20 -> -0.169209 | F34: R$/kWh. Desconsiderar se é grupo B
A35: (Grupo A) Demanda de geração contratada ótima | E35: =E40*(1-Payback!E5) -> 3347.8261 | F35: W, aproximado
A36: Potência Fotovoltaica teórica | E36: =E30*1000/(30*E22*E13) -> 5126.3596 | F36: W; PFV=1000*EFV/(30*GHI*ηsis).
A37: Número de módulos | E37: =ROUNDUP(E36/E23,0) -> 10 | F37: (Arredondado pra cima).
A38: Nº de módulos/Nº de MPPT | E38: =ROUND(E37/E27,0) -> 5
A39: Potência Fotovoltaica real | E39: =E37*E23 -> 5500 | F39: W (com nº inteiro de módulos).
A40: Potência do Inversor em CA | E40: =E39/E24 -> 4782.6087 | F40: W; aproximado.
A41: Energia Fotovoltaica real | E41: =30*E13*E22*E39/1000 -> 687.72 | F41: Geração estimada.
A42: Tensão máxima por MPPT | E42: =E25*(1+(E10-25)*E26)*E38 -> 262.384 | F42: Conferir datasheet e ver se o inversor suporta, precisa de VMPPTmax_Inverter_Datasheet > do que este valor.
A43: Inclinação ideal | E43: =IF(E11<10,10,IF(E11<=20,E11,IF(E11<=30,E11+5,IF(E11<=40,E11+10,E11+15)))) -> 28 | F43: º/Norte; escolha ótima se for possível escolher a inclinação (compensa pela inclinação da latitude).
...

Sheet Payback
B1: Viabilidade Econômica
G2: Dados alteráveis: | O2: Células Auxiliares + Porcentagem FioB (desconta na injetada)
B3: Fatores de Influência Adotados | E3: Valor | G3: Dados fixos: | O3: TE_ef | P3: =IF(Dimensionamento!$E$7="A",Dimensionamento!$E$17,Dimensionamento!$E$15) -> 0.30905
B4: Previsão de aumento do custo Energia | E4: 0.05 | F4: /ano | H4: Baseado no aumento médio do custo da energia nos últimos anos. | O4: TUSD_ef | P4: =IF(Dimensionamento!$E$7="A",Dimensionamento!$E$16,Dimensionamento!$E$14) -> 0.44925
B5: Taxa de Autoconsumo | E5: 0.3 | F5: *Qnt. geração usada para suprir o próprio consumo, não injetada - escolher entre 20-40% se não houver armazenamento (BESS); com BESS, depende da estratégia adotada no sistema. | O5: FioB_ef | P5: =Dimensionamento!E19 -> 0.18801
B6: Taxa de Desconto | E6: 0.1 | F6: /ano | H6: Taxa usada para cálculo do Fluxo Descontado e VPL. | O6: Porcentagem Fio B | P6: =Dimensionamento!$E$20 -> 0.9 | Q6: 90% = base (2029) até nova resolução ANEEL.
B7: Vida útil do inversor | E7: 15 | F7: anos | H7: Estimativa.
B8: Custo de manutenção em relação à economia anual | E8: 0.02 | F8: Em torno de 1%-5% do custo de Energia Gerada para limpeza do módulos.
B9: Custos total do inversor em relação à economia anual | E9: 0.7 | F9: Em torno de 30-70%. Apenas para efeitos de troca do inversor após a vida útil.
B10: Perda de eficiencia do painel | E10: 0.02 | F10: 1º ano.
B11: Perda de eficiencia do painel (outros anos) | E11: 0.008 | F11: 2º ano em diante.
B12: Cenário: Pessimista (1); Base (2); Otimista (3) | E12: 2 | F12: *Será decidido pela ANEEL nova valorização da energia injetável. Escolhi cenário 1: só vale TE; cenário 2: TE+TUSD-FioB*%; cenário 3: preço cheio, TE+TUSD (teto, benefícios).
J13: Payback simples | L13: Payback descontado (supondo desvalorização)
C14: Ano | D14: Energia Anual Gerada (kWh) | E14: Custo do kWh de Energia Consumida (R$) | F14: Custo do kWh de Energia Injetada (R$) | G14: Economia (R$) | H14: Manutenção (R$) | I14: Fluxo de Caixa Anual (R$) | J14: Fluxo Acumulado (R$) | K14: Fluxo Descontado (R$) | L14: Fluxo Descontado Acumulado (R$)
C15: 0 | I15: =-Dimensionamento!G73 -> -26413.91 | J15: =I15 -> -26413.91 | K15: =I15 -> -26413.91 | L15: =I15 -> -26413.91
C16: 1 | D16: =Dimensionamento!E41*12 -> 8252.64 | E16: =P3+P4 -> 0.7583 | F16: =IF($E$12=1, $P$3,IF($E$12=2, $P$3+$P$4-$P$5*$P$6,$P$3+$P$4)) -> 0.589091 | G16: =(E16*$E$5+(1-$E$5)*F16)*D16 -> 5280.4822 | H16: =IF(OR(C16=$E$7,C16=2*$E$7),G16*($E$8+$E$9),G16*$E$8) -> 105.60964 | I16: =G16-H16- IF(Dimensionamento!$E$7="A", Dimensionamento!$E$35*Dimensionamento!$E$18*12, 0) -> 5174.8726 | J16: =J15+I16 -> -21239.037 | K16: =I16/(1+$E$6)^C16 -> 4704.4296 | L16: =L15+K16 -> -21709.48
C17: 2 | D17: =Dimensionamento!$E$41*12*(1-$E$10) -> 8087.5872 | E17: =E16*(1+$E$4) -> 0.796215 | F17: =F16*(1+$E$4) -> 0.61854555 | G17: =(E17*$E$5+(1-$E$5)*F17)*D17 -> 5433.6162 | H17: =IF(OR(C17=$E$7,C17=2*$E$7),G17*($E$8+$E$9),G17*$E$8) -> 108.67232 | I17: =G17-H17- IF(Dimensionamento!$E$7="A", Dimensionamento!$E$35*Dimensionamento!$E$18*12, 0) -> 5324.9439 | J17: =J16+I17 -> -15914.094 | K17: =I17/(1+$E$6)^C17 -> 4400.7801 | L17: =L16+K17 -> -17308.7
C18: 3 | D18: =Dimensionamento!$E$41*12*(1-$E$10-(C18-2)*$E$11) -> 8021.5661 | E18: =E17*(1+$E$4) -> 0.83602575 | F18: =F17*(1+$E$4) -> 0.64947283 | G18: =(E18*$E$5+(1-$E$5)*F18)*D18 -> 5658.7232 | H18: =IF(OR(C18=$E$7,C18=2*$E$7),G18*($E$8+$E$9),G18*$E$8) -> 113.17446 | I18: =G18-H18- IF(Dimensionamento!$E$7="A", Dimensionamento!$E$35*Dimensionamento!$E$18*12, 0) -> 5545.5487 | J18: =J17+I18 -> -10368.545 | K18: =I18/(1+$E$6)^C18 -> 4166.4528 | L18: =L17+K18 -> -13142.247
C19: 4 | D19: =Dimensionamento!$E$41*12*(1-$E$10-(C19-2)*$E$11) -> 7955.545 | E19: =E18*(1+$E$4) -> 0.87782704 | F19: =F18*(1+$E$4) -> 0.68194647 | G19: =(E19*$E$5+(1-$E$5)*F19)*D19 -> 5892.7568 | H19: =IF(OR(C19=$E$7,C19=2*$E$7),G19*($E$8+$E$9),G19*$E$8) -> 117.85514 | I19: =G19-H19- IF(Dimensionamento!$E$7="A", Dimensionamento!$E$35*Dimensionamento!$E$18*12, 0) -> 5774.9017 | J19: =J18+I19 -> -4593.6431 | K19: =I19/(1+$E$6)^C19 -> 3944.3355 | L19: =L18+K19 -> -9197.9119
C20: 5 | D20: =Dimensionamento!$E$41*12*(1-$E$10-(C20-2)*$E$11) -> 7889.5238 | E20: =E19*(1+$E$4) -> 0.92171839 | F20: =F19*(1+$E$4) -> 0.71604379 | G20: =(E20*$E$5+(1-$E$5)*F20)*D20 -> 6136.047 | H20: =IF(OR(C20=$E$7,C20=2*$E$7),G20*($E$8+$E$9),G20*$E$8) -> 122.72094 | I20: =G20-H20- IF(Dimensionamento!$E$7="A", Dimensionamento!$E$35*Dimensionamento!$E$18*12, 0) -> 6013.326 | J20: =J19+I20 -> 1419.6829 | K20: =I20/(1+$E$6)^C20 -> 3733.8023 | L20: =L19+K20 -> -5464.1096
C21: 6 | D21: =Dimensionamento!$E$41*12*(1-$E$10-(C21-2)*$E$11) -> 7823.5027 | E21: =E20*(1+$E$4) -> 0.96780431 | F21: =F20*(1+$E$4) -> 0.75184598 | G21: =(E21*$E$5+(1-$E$5)*F21)*D21 -> 6388.9343 | H21: =IF(OR(C21=$E$7,C21=2*$E$7),G21*($E$8+$E$9),G21*$E$8) -> 127.77869 | I21: =G21-H21- IF(Dimensionamento!$E$7="A", Dimensionamento!$E$35*Dimensionamento!$E$18*12, 0) -> 6261.1556 | J21: =J20+I21 -> 7680.8385 | K21: =I21/(1+$E$6)^C21 -> 3534.2591 | L21: =L20+K21 -> -1929.8505
C22: 7 | D22: =Dimensionamento!$E$41*12*(1-$E$10-(C22-2)*$E$11) -> 7757.4816 | E22: =E21*(1+$E$4) -> 1.0161945 | F22: =F21*(1+$E$4) -> 0.78943828 | G22: =(E22*$E$5+(1-$E$5)*F22)*D22 -> 6651.7702 | H22: =IF(OR(C22=$E$7,C22=2*$E$7),G22*($E$8+$E$9),G22*$E$8) -> 133.0354 | I22: =G22-H22- IF(Dimensionamento!$E$7="A", Dimensionamento!$E$35*Dimensionamento!$E$18*12, 0) -> 6518.7348 | J22: =J21+I22 -> 14199.573 | K22: =I22/(1+$E$6)^C22 -> 3345.1417 | L22: =L21+K22 -> 1415.2912
C23: 8 | D23: =Dimensionamento!$E$41*12*(1-$E$10-(C23-2)*$E$11) -> 7691.4605 | E23: =E22*(1+$E$4) -> 1.0670043 | F23: =F22*(1+$E$4) -> 0.8289102 | G23: =(E23*$E$5+(1-$E$5)*F23)*D23 -> 6924.9173 | H23: =IF(OR(C23=$E$7,C23=2*$E$7),G23*($E$8+$E$9),G23*$E$8) -> 138.49835 | I23: =G23-H23- IF(Dimensionamento!$E$7="A", Dimensionamento!$E$35*Dimensionamento!$E$18*12, 0) -> 6786.419 | J23: =J22+I23 -> 20985.992 | K23: =I23/(1+$E$6)^C23 -> 3165.9145 | L23: =L22+K23 -> 4581.2057
C24: 9 | D24: =Dimensionamento!$E$41*12*(1-$E$10-(C24-2)*$E$11) -> 7625.4394 | E24: =E23*(1+$E$4) -> 1.1203545 | F24: =F23*(1+$E$4) -> 0.8703557 | G24: =(E24*$E$5+(1-$E$5)*F24)*D24 -> 7208.7498 | H24: =IF(OR(C24=$E$7,C24=2*$E$7),G24*($E$8+$E$9),G24*$E$8) -> 144.175 | I24: =G24-H24- IF(Dimensionamento!$E$7="A", Dimensionamento!$E$35*Dimensionamento!$E$18*12, 0) -> 7064.5748 | J24: =J23+I24 -> 28050.567 | K24: =I24/(1+$E$6)^C24 -> 2996.0693 | L24: =L23+K24 -> 7577.275
C25: 10 | D25: =Dimensionamento!$E$41*12*(1-$E$10-(C25-2)*$E$11) -> 7559.4182 | E25: =E24*(1+$E$4) -> 1.1763722 | F25: =F24*(1+$E$4) -> 0.91387349 | G25: =(E25*$E$5+(1-$E$5)*F25)*D25 -> 7503.6532 | H25: =IF(OR(C25=$E$7,C25=2*$E$7),G25*($E$8+$E$9),G25*$E$8) -> 150.07306 | I25: =G25-H25- IF(Dimensionamento!$E$7="A", Dimensionamento!$E$35*Dimensionamento!$E$18*12, 0) -> 7353.5801 | J25: =J24+I25 -> 35404.147 | K25: =I25/(1+$E$6)^C25 -> 2835.1235 | L25: =L24+K25 -> 10412.399
C26: 11 | D26: =Dimensionamento!$E$41*12*(1-$E$10-(C26-2)*$E$11) -> 7493.3971 | E26: =E25*(1+$E$4) -> 1.2351908 | F26: =F25*(1+$E$4) -> 0.95956716 | G26: =(E26*$E$5+(1-$E$5)*F26)*D26 -> 7810.025 | H26: =IF(OR(C26=$E$7,C26=2*$E$7),G26*($E$8+$E$9),G26*$E$8) -> 156.2005 | I26: =G26-H26- IF(Dimensionamento!$E$7="A", Dimensionamento!$E$35*Dimensionamento!$E$18*12, 0) -> 7653.8245 | J26: =J25+I26 -> 43057.972 | K26: =I26/(1+$E$6)^C26 -> 2682.6188 | L26: =L25+K26 -> 13095.017
C27: 12 | D27: =Dimensionamento!$E$41*12*(1-$E$10-(C27-2)*$E$11) -> 7427.376 | E27: =E26*(1+$E$4) -> 1.2969503 | F27: =F26*(1+$E$4) -> 1.0075455 | G27: =(E27*$E$5+(1-$E$5)*F27)*D27 -> 8128.2749 | H27: =IF(OR(C27=$E$7,C27=2*$E$7),G27*($E$8+$E$9),G27*$E$8) -> 162.5655 | I27: =G27-H27- IF(Dimensionamento!$E$7="A", Dimensionamento!$E$35*Dimensionamento!$E$18*12, 0) -> 7965.7094 | J27: =J26+I27 -> 51023.681 | K27: =I27/(1+$E$6)^C27 -> 2538.1205 | L27: =L26+K27 -> 15633.138
C28: 13 | D28: =Dimensionamento!$E$41*12*(1-$E$10-(C28-2)*$E$11) -> 7361.3549 | E28: =E27*(1+$E$4) -> 1.3617979 | F28: =F27*(1+$E$4) -> 1.0579228 | G28: =(E28*$E$5+(1-$E$5)*F28)*D28 -> 8458.8248 | H28: =IF(OR(C28=$E$7,C28=2*$E$7),G28*($E$8+$E$9),G28*$E$8) -> 169.1765 | I28: =G28-H28- IF(Dimensionamento!$E$7="A", Dimensionamento!$E$35*Dimensionamento!$E$18*12, 0) -> 8289.6483 | J28: =J27+I28 -> 59313.329 | K28: =I28/(1+$E$6)^C28 -> 2401.2158 | L28: =L27+K28 -> 18034.354
C29: 14 | D29: =Dimensionamento!$E$41*12*(1-$E$10-(C29-2)*$E$11) -> 7295.3338 | E29: =E28*(1+$E$4) -> 1.4298877 | F29: =F28*(1+$E$4) -> 1.1108189 | G29: =(E29*$E$5+(1-$E$5)*F29)*D29 -> 8802.1089 | H29: =IF(OR(C29=$E$7,C29=2*$E$7),G29*($E$8+$E$9),G29*$E$8) -> 176.04218 | I29: =G29-H29- IF(Dimensionamento!$E$7="A", Dimensionamento!$E$35*Dimensionamento!$E$18*12, 0) -> 8626.0668 | J29: =J28+I29 -> 67939.396 | K29: =I29/(1+$E$6)^C29 -> 2271.513 | L29: =L28+K29 -> 20305.867
... C45: 30 | D45: =Dimensionamento!$E$41*12*(1-$E$10-(C45-2)*$E$11) -> 6238.9958 | E45: =E44*(1+$E$4) -> 3.1212656 | F45: =F44*(1+$E$4) -> 2.4247784 | G45: =(E45*$E$5+(1-$E$5)*F45)*D45 -> 16431.797 | H45: =IF(OR(C45=$E$7,C45=2*$E$7),G45*($E$8+$E$9),G45*$E$8) -> 11830.894 | I45: =G45-H45- IF(Dimensionamento!$E$7="A", Dimensionamento!$E$35*Dimensionamento!$E$18*12, 0) -> 4600.9031 | J45: =J44+I45 -> 245827.86 | K45: =I45/(1+$E$6)^C45 -> 263.6711 | L45: =L44+K45 -> 41448.413
C48: VPL | D48: =SUM(K15:K45) -> 41448.413
C49: TIR | D49: =IRR(I15:I45) -> 0.23161171
B51: VPL: Soma de todos os fluxos de caixa trazidos a valor presente pela taxa de desconto, incluindo o investimento inicial. Representa o ganho líquido do projeto em valores de hoje. VPL > 0 indica que o projeto se paga e ainda gera retorno acima da taxa de desconto adotada. Sua progressão pode ser vista no fluxo descontado.
B55: TIR: Taxa de desconto que zera o VPL; representa a rentabilidade equivalente do investimento.
