Workbook

Sheet Dimensionamento
A1: Pedro Kzan - Eng. Elétrica | EESC USP
A3: Dimensionamento de Sistema Fotovoltaico ON-GRID para usuário micro ou minigerador com Payback - Dimens. Inicial
G5: Legenda: | H5: Dados alteráveis:
A6: Dados Indicados (inputs) | H6: Dados fixos:
A7: Classe do Usuário | E7: A | F7: Disponível na conta de energia, assim como o modelo tarifário.
A8: Modelo tarifário | E8: Azul | F8: À direita das células preenchíveis, seguem explicações.
A9: Cidade | E9: São Carlos
A10: Tmin | F10: ºC. | H10: Energia de Custo de Disponibilidade (Grupo B): | K10: Sistema monofásico: 30kWh
A11: Latitude | E11: 23 | F11: º/Sul. | K11: Sistema bifásico (3 fios): 50kWh
A12: Longitude | F12: º/Oeste. | K12: Sistema trifásico: 100kWh
A13: Irradiação Solar (GHI) | F13: *Sundata.
A14: (Grupo B) custo consumo TUSD (R$/kWh) | F14: Da conta de energia, disponível lá ou publicamente pela concessionária.
A15: (Grupo B) custo consumo TE (R$/kWh) | F15: Se não há TUSD e TE separados na conta de energia, considere TE=TUSD.
A16: (Grupo A) consumo Fponta TUSD | F16: TE: custo da energia; TUSD: custo do transporte dela.
A17: (Grupo A) consumo Fponta TE | F17: Por fins de aproximação, desconsidero a ponta para o cálculo de Payback pois em Pernambuco ponta começa às 17:30, mas no horário a geração é tão pouca que desconsidero para facilitar cálculos.
A18: (Grupo A) custo demanda de geração TUSDG
A19: Fio B | F19: No site da ANEEL: Assuntos → Tarifas → Relatórios e Indicadores → Base de Dados das Tarifas das Distribuidoras, na opção "Componentes Tarifárias". Você preenche distribuidora, grupo, subgrupo, modalidade e classe, e lê a TUSD Fio B direto, sem imposto.
A20: Porcentagem fio B | E20: 0.9 | F20: 90% = base 2029, irá mudar com nova resolução ANEEL
A21: Energia Mensal (EM) | F21: kWh/mês.
A22: Eficiência do sistema todo (ηsis) | F22: Escolher entre [0,7-0,9] -> perdas surgem de temperatura, inversor, sujeira/poeira, cabeamento, mismatch, sombreamento, degradação.
A23: Potência do Painel (PMOD) | F23: W -> escolha do projetista.
A24: Sobrecarga do Inversor (PCC/PCA) | F24: Escolher entre [1-1,25] -> conferir no manual do inversor.
A25: Tensão em Vazio do Módulo | F25: V vide datasheet do módulo.
A26: Coeficiente de temperatura do módulo (α) | F26: Vide datasheet do módulo.
A27: Nº de MPPTs do Inversor | F27: Conexões no inversor.
A29: Dimensionamento Preliminar (outputs)
A30: Consumo de energia do cliente | E30: =E21 -> 0 | F30: Energia média mensal (kWh/mês) obtida da conta de energia; média dos últimos 12 meses.
A31: (Grupo B) Custo de energia consumida | E31: =(E14+E15) -> 0 | F31: R$/kWh.
A32: (Grupo A) custo energia injetada | E32: =#REF!+#REF! -> #REF! | F32: R$/kWh.
A33: (Grupo A) custo E consumo Fponta | E33: =E16+E17 -> 0 | F33: R$/kWh.
A34: (Grupo B) custo de energia injetada | E34: =E14+E15-E19*Payback!$P$6 -> 0 | F34: Crédito por kWh injetado (Lei 14.300). TUSD*(1-ICMS) + TE.
A35: (Grupo A) Demanda de geração contratada ótima | E35: =E40/1000*(1-Payback!E5) -> #DIV/0!
A36: Potência Fotovoltaica teórica | E36: =E30*1000/(30*E22*E13) -> #DIV/0! | F36: W; PFV=1000*EFV/(30*GHI*ηsis).
A37: Número de módulos | E37: =ROUNDUP(E36/E23,0) -> #DIV/0! | F37: (Arredondado pra cima).
A38: Nº de módulos/Nº de MPPT | E38: =ROUND(E37/E27,0) -> #DIV/0!
A39: Potência Fotovoltaica real | E39: =E37*E23 -> #DIV/0! | F39: W (com nº inteiro de módulos).
A40: Potência do Inversor em CA | E40: =E39/E24 -> #DIV/0! | F40: Aproximado.
A41: Energia Fotovoltaica real | E41: =30*E13*E22*E39/1000 -> #DIV/0! | F41: Geração estimada.
A42: Tensão máxima por MPPT | E42: =E25*(1+(E10-25)*E26)*E38 -> #DIV/0! | F42: Conferir datasheet e ver se o inversor suporta, precisa de VMPPTmax_Inverter_Datasheet > do que este valor.
A43: Inclinação ideal | E43: =IF(E11<10,10,IF(E11<=20,E11,IF(E11<=30,E11+5,IF(E11<=40,E11+10,E11+15)))) -> 28 | F43: Escolha ótima, se for possível escolher a inclinação (compensa pela inclinação da latitude).
...

Sheet Payback
B1: Viabilidade Econômica
G2: Dados alteráveis: | O2: Células Auxiliares + Porcentagem FioB (desconta na injetada)
B3: Fatores de Influência Adotados | E3: Valor | G3: Dados fixos: | O3: TE_ef | P3: =IF(Dimensionamento!$E$7="A",Dimensionamento!$E$17,Dimensionamento!$E$15) -> 0
B4: Previsão de aumento do custo Energia | F4: /ano | H4: Baseado no aumento médio do custo da energia nos últimos anos. | O4: TUSD_ef | P4: =IF(Dimensionamento!$E$7="A",Dimensionamento!$E$16,Dimensionamento!$E$14) -> 0
B5: Taxa de Autoconsumo | F5: *Qnt. geração usada para suprir o próprio consumo, não injetada - escolher entre 20-40% se não houver armazenamento (BESS); com BESS, depende da estratégia adotada no sistema. | O5: FioB_ef | P5: =Dimensionamento!E19 -> 0
B6: Taxa de Desconto | F6: /ano | H6: Taxa usada para cálculo do Fluxo Descontado e VPL. | O6: Porcentagem Fio B | P6: =Dimensionamento!$E$20 -> 0.9 | Q6: 90% = base (2029) até nova resolução ANEEL.
B7: Vida útil do inversor | F7: anos | H7: Estimativa.
B8: Custo de manutenção em relação à economia anual | F8: Em torno de 1%-5% do custo de Energia Gerada para limpeza do módulos..=
B9: Custos total do inversor em relação à economia anual | F9: Em torno de 30-70%. Apenas para efeitos de troca do inversor após a vida útil.
B10: Perda de eficiencia do painel | E10: 0.02 | F10: 1º ano.
B11: Perda de eficiencia do painel (outros anos) | E11: 0.008 | F11: 2º ano em diante.
B12: Cenário: Pessimista (1); Base (2); Otimista (3) | E12: 2 | F12: *Será decidido pela ANEEL nova valorização da energia injetável. Escolhi cenário 1: só vale TE; cenário 2: TE+TUSD-FioB*%; cenário 3: preço cheio, TE+TUSD (teto, benefícios).
J13: Payback simples | L13: Payback descontado (supondo desvalorização)
C14: Ano | D14: Energia Anual Gerada (kWh) | E14: Custo do kWh de Energia Consumida (R$) | F14: Custo do kWh de Energia Injetada (R$) | G14: Economia (R$) | H14: Manutenção (R$) | I14: Fluxo de Caixa Anual (R$) | J14: Fluxo Acumulado (R$) | K14: Fluxo Descontado (R$) | L14: Fluxo Descontado Acumulado (R$)
C15: 0 | I15: =-Dimensionamento!G73 -> -25800 | J15: =I15 -> -25800 | K15: =I15 -> -25800 | L15: =I15 -> -25800
C16: 1 | D16: =Dimensionamento!E41*12 -> #DIV/0! | E16: =P3+P4 -> 0 | F16: =IF($E$12=1, $P$3,IF($E$12=2, $P$3+$P$4-$P$5*$P$6,$P$3+$P$4)) -> 0 | G16: =(E16*$E$5+(1-$E$5)*F16)*D16 -> #DIV/0! | H16: =IF(OR(C16=$E$7,C16=2*$E$7),G16*($E$8+$E$9),G16*$E$8) -> #DIV/0! | I16: =G16-H16- IF(Dimensionamento!$E$7="A", Dimensionamento!$E$35*Dimensionamento!$E$18*12, 0) -> #DIV/0! | J16: =J15+I16 -> #DIV/0! | K16: =I16/(1+$E$6)^C16 -> #DIV/0! | L16: =L15+K16 -> #DIV/0!
C17: 2 | D17: =Dimensionamento!$E$41*12*(1-$E$10) -> #DIV/0! | E17: =E16*(1+$E$4) -> 0 | F17: =F16*(1+$E$4) -> 0 | G17: =(E17*$E$5+(1-$E$5)*F17)*D17 -> #DIV/0! | H17: =IF(OR(C17=$E$7,C17=2*$E$7),G17*($E$8+$E$9),G17*$E$8) -> #DIV/0! | I17: =G17-H17- IF(Dimensionamento!$E$7="A", Dimensionamento!$E$35*Dimensionamento!$E$18*12, 0) -> #DIV/0! | J17: =J16+I17 -> #DIV/0! | K17: =I17/(1+$E$6)^C17 -> #DIV/0! | L17: =L16+K17 -> #DIV/0!
C18: 3 | D18: =Dimensionamento!$E$41*12*(1-$E$10-(C18-2)*$E$11) -> #DIV/0! | E18: =E17*(1+$E$4) -> 0 | F18: =F17*(1+$E$4) -> 0 | G18: =(E18*$E$5+(1-$E$5)*F18)*D18 -> #DIV/0! | H18: =IF(OR(C18=$E$7,C18=2*$E$7),G18*($E$8+$E$9),G18*$E$8) -> #DIV/0! | I18: =G18-H18- IF(Dimensionamento!$E$7="A", Dimensionamento!$E$35*Dimensionamento!$E$18*12, 0) -> #DIV/0! | J18: =J17+I18 -> #DIV/0! | K18: =I18/(1+$E$6)^C18 -> #DIV/0! | L18: =L17+K18 -> #DIV/0!
C19: 4 | D19: =Dimensionamento!$E$41*12*(1-$E$10-(C19-2)*$E$11) -> #DIV/0! | E19: =E18*(1+$E$4) -> 0 | F19: =F18*(1+$E$4) -> 0 | G19: =(E19*$E$5+(1-$E$5)*F19)*D19 -> #DIV/0! | H19: =IF(OR(C19=$E$7,C19=2*$E$7),G19*($E$8+$E$9),G19*$E$8) -> #DIV/0! | I19: =G19-H19- IF(Dimensionamento!$E$7="A", Dimensionamento!$E$35*Dimensionamento!$E$18*12, 0) -> #DIV/0! | J19: =J18+I19 -> #DIV/0! | K19: =I19/(1+$E$6)^C19 -> #DIV/0! | L19: =L18+K19 -> #DIV/0!
C20: 5 | D20: =Dimensionamento!$E$41*12*(1-$E$10-(C20-2)*$E$11) -> #DIV/0! | E20: =E19*(1+$E$4) -> 0 | F20: =F19*(1+$E$4) -> 0 | G20: =(E20*$E$5+(1-$E$5)*F20)*D20 -> #DIV/0! | H20: =IF(OR(C20=$E$7,C20=2*$E$7),G20*($E$8+$E$9),G20*$E$8) -> #DIV/0! | I20: =G20-H20- IF(Dimensionamento!$E$7="A", Dimensionamento!$E$35*Dimensionamento!$E$18*12, 0) -> #DIV/0! | J20: =J19+I20 -> #DIV/0! | K20: =I20/(1+$E$6)^C20 -> #DIV/0! | L20: =L19+K20 -> #DIV/0!
C21: 6 | D21: =Dimensionamento!$E$41*12*(1-$E$10-(C21-2)*$E$11) -> #DIV/0! | E21: =E20*(1+$E$4) -> 0 | F21: =F20*(1+$E$4) -> 0 | G21: =(E21*$E$5+(1-$E$5)*F21)*D21 -> #DIV/0! | H21: =IF(OR(C21=$E$7,C21=2*$E$7),G21*($E$8+$E$9),G21*$E$8) -> #DIV/0! | I21: =G21-H21- IF(Dimensionamento!$E$7="A", Dimensionamento!$E$35*Dimensionamento!$E$18*12, 0) -> #DIV/0! | J21: =J20+I21 -> #DIV/0! | K21: =I21/(1+$E$6)^C21 -> #DIV/0! | L21: =L20+K21 -> #DIV/0!
C22: 7 | D22: =Dimensionamento!$E$41*12*(1-$E$10-(C22-2)*$E$11) -> #DIV/0! | E22: =E21*(1+$E$4) -> 0 | F22: =F21*(1+$E$4) -> 0 | G22: =(E22*$E$5+(1-$E$5)*F22)*D22 -> #DIV/0! | H22: =IF(OR(C22=$E$7,C22=2*$E$7),G22*($E$8+$E$9),G22*$E$8) -> #DIV/0! | I22: =G22-H22- IF(Dimensionamento!$E$7="A", Dimensionamento!$E$35*Dimensionamento!$E$18*12, 0) -> #DIV/0! | J22: =J21+I22 -> #DIV/0! | K22: =I22/(1+$E$6)^C22 -> #DIV/0! | L22: =L21+K22 -> #DIV/0!
C23: 8 | D23: =Dimensionamento!$E$41*12*(1-$E$10-(C23-2)*$E$11) -> #DIV/0! | E23: =E22*(1+$E$4) -> 0 | F23: =F22*(1+$E$4) -> 0 | G23: =(E23*$E$5+(1-$E$5)*F23)*D23 -> #DIV/0! | H23: =IF(OR(C23=$E$7,C23=2*$E$7),G23*($E$8+$E$9),G23*$E$8) -> #DIV/0! | I23: =G23-H23- IF(Dimensionamento!$E$7="A", Dimensionamento!$E$35*Dimensionamento!$E$18*12, 0) -> #DIV/0! | J23: =J22+I23 -> #DIV/0! | K23: =I23/(1+$E$6)^C23 -> #DIV/0! | L23: =L22+K23 -> #DIV/0!
C24: 9 | D24: =Dimensionamento!$E$41*12*(1-$E$10-(C24-2)*$E$11) -> #DIV/0! | E24: =E23*(1+$E$4) -> 0 | F24: =F23*(1+$E$4) -> 0 | G24: =(E24*$E$5+(1-$E$5)*F24)*D24 -> #DIV/0! | H24: =IF(OR(C24=$E$7,C24=2*$E$7),G24*($E$8+$E$9),G24*$E$8) -> #DIV/0! | I24: =G24-H24- IF(Dimensionamento!$E$7="A", Dimensionamento!$E$35*Dimensionamento!$E$18*12, 0) -> #DIV/0! | J24: =J23+I24 -> #DIV/0! | K24: =I24/(1+$E$6)^C24 -> #DIV/0! | L24: =L23+K24 -> #DIV/0!
C25: 10 | D25: =Dimensionamento!$E$41*12*(1-$E$10-(C25-2)*$E$11) -> #DIV/0! | E25: =E24*(1+$E$4) -> 0 | F25: =F24*(1+$E$4) -> 0 | G25: =(E25*$E$5+(1-$E$5)*F25)*D25 -> #DIV/0! | H25: =IF(OR(C25=$E$7,C25=2*$E$7),G25*($E$8+$E$9),G25*$E$8) -> #DIV/0! | I25: =G25-H25- IF(Dimensionamento!$E$7="A", Dimensionamento!$E$35*Dimensionamento!$E$18*12, 0) -> #DIV/0! | J25: =J24+I25 -> #DIV/0! | K25: =I25/(1+$E$6)^C25 -> #DIV/0! | L25: =L24+K25 -> #DIV/0!
C26: 11 | D26: =Dimensionamento!$E$41*12*(1-$E$10-(C26-2)*$E$11) -> #DIV/0! | E26: =E25*(1+$E$4) -> 0 | F26: =F25*(1+$E$4) -> 0 | G26: =(E26*$E$5+(1-$E$5)*F26)*D26 -> #DIV/0! | H26: =IF(OR(C26=$E$7,C26=2*$E$7),G26*($E$8+$E$9),G26*$E$8) -> #DIV/0! | I26: =G26-H26- IF(Dimensionamento!$E$7="A", Dimensionamento!$E$35*Dimensionamento!$E$18*12, 0) -> #DIV/0! | J26: =J25+I26 -> #DIV/0! | K26: =I26/(1+$E$6)^C26 -> #DIV/0! | L26: =L25+K26 -> #DIV/0!
C27: 12 | D27: =Dimensionamento!$E$41*12*(1-$E$10-(C27-2)*$E$11) -> #DIV/0! | E27: =E26*(1+$E$4) -> 0 | F27: =F26*(1+$E$4) -> 0 | G27: =(E27*$E$5+(1-$E$5)*F27)*D27 -> #DIV/0! | H27: =IF(OR(C27=$E$7,C27=2*$E$7),G27*($E$8+$E$9),G27*$E$8) -> #DIV/0! | I27: =G27-H27- IF(Dimensionamento!$E$7="A", Dimensionamento!$E$35*Dimensionamento!$E$18*12, 0) -> #DIV/0! | J27: =J26+I27 -> #DIV/0! | K27: =I27/(1+$E$6)^C27 -> #DIV/0! | L27: =L26+K27 -> #DIV/0!
C28: 13 | D28: =Dimensionamento!$E$41*12*(1-$E$10-(C28-2)*$E$11) -> #DIV/0! | E28: =E27*(1+$E$4) -> 0 | F28: =F27*(1+$E$4) -> 0 | G28: =(E28*$E$5+(1-$E$5)*F28)*D28 -> #DIV/0! | H28: =IF(OR(C28=$E$7,C28=2*$E$7),G28*($E$8+$E$9),G28*$E$8) -> #DIV/0! | I28: =G28-H28- IF(Dimensionamento!$E$7="A", Dimensionamento!$E$35*Dimensionamento!$E$18*12, 0) -> #DIV/0! | J28: =J27+I28 -> #DIV/0! | K28: =I28/(1+$E$6)^C28 -> #DIV/0! | L28: =L27+K28 -> #DIV/0!
C29: 14 | D29: =Dimensionamento!$E$41*12*(1-$E$10-(C29-2)*$E$11) -> #DIV/0! | E29: =E28*(1+$E$4) -> 0 | F29: =F28*(1+$E$4) -> 0 | G29: =(E29*$E$5+(1-$E$5)*F29)*D29 -> #DIV/0! | H29: =IF(OR(C29=$E$7,C29=2*$E$7),G29*($E$8+$E$9),G29*$E$8) -> #DIV/0! | I29: =G29-H29- IF(Dimensionamento!$E$7="A", Dimensionamento!$E$35*Dimensionamento!$E$18*12, 0) -> #DIV/0! | J29: =J28+I29 -> #DIV/0! | K29: =I29/(1+$E$6)^C29 -> #DIV/0! | L29: =L28+K29 -> #DIV/0!
... C45: 30 | D45: =Dimensionamento!$E$41*12*(1-$E$10-(C45-2)*$E$11) -> #DIV/0! | E45: =E44*(1+$E$4) -> 0 | F45: =F44*(1+$E$4) -> 0 | G45: =(E45*$E$5+(1-$E$5)*F45)*D45 -> #DIV/0! | H45: =IF(OR(C45=$E$7,C45=2*$E$7),G45*($E$8+$E$9),G45*$E$8) -> #DIV/0! | I45: =G45-H45- IF(Dimensionamento!$E$7="A", Dimensionamento!$E$35*Dimensionamento!$E$18*12, 0) -> #DIV/0! | J45: =J44+I45 -> #DIV/0! | K45: =I45/(1+$E$6)^C45 -> #DIV/0! | L45: =L44+K45 -> #DIV/0!
C48: VPL | D48: =SUM(K15:K45) -> #DIV/0!
C49: TIR | D49: =IRR(I15:I45) -> #VALUE!
B51: VPL: Soma de todos os fluxos de caixa trazidos a valor presente pela taxa de desconto, incluindo o investimento inicial. Representa o ganho líquido do projeto em valores de hoje. VPL > 0 indica que o projeto se paga e ainda gera retorno acima da taxa de desconto adotada. Sua progressão pode ser vista no fluxo descontado.
B55: TIR: Taxa de desconto que zera o VPL; representa a rentabilidade equivalente do investimento.
